<?xml version="1.0" ?>
<robot name="Robot" xmlns:xacro="http://www.ros.org/wiki/xacro">

<xacro:macro name="Robot" params="prefix">

<xacro:include filename="$(find Robot_description)/urdf/materials.xacro" />
<xacro:include filename="$(find Robot_description)/urdf/Robot.trans" />
<xacro:include filename="$(find Robot_description)/urdf/Robot.gazebo" />
<link name="${prefix}base_link"/>

<link name="${prefix}37">
  <inertial>
    <origin xyz="-0.14013206527441066 0.028512924200930104 0.12852934252140233" rpy="0 0 0"/>
    <mass value="0.03413800341133604"/>
    <inertia ixx="1.1e-05" iyy="1.1e-05" izz="1.2e-05" ixy="-4e-06" iyz="-0.0" ixz="-0.0"/>
  </inertial>
  <visual>
    <origin xyz="0 0 0" rpy="0 0 0"/>
    <geometry>
      <mesh filename="package://Robot_description/meshes/37.stl" scale="0.001 0.001 0.001"/>
    </geometry>
    <material name="Robot_silver"/>
  </visual>
  <collision>
    <origin xyz="0 0 0" rpy="0 0 0"/>
    <geometry>
      <mesh filename="package://Robot_description/meshes/37.stl" scale="0.001 0.001 0.001"/>
    </geometry>
  </collision>
</link>

<link name="${prefix}Lidar">
  <inertial>
    <origin xyz="-0.049824473202757555 0.16302584059432873 0.0453597501925487" rpy="0 0 0"/>
    <mass value="1.2846085438911172"/>
    <inertia ixx="0.002966" iyy="0.002973" izz="0.00143" ixy="-3e-06" iyz="2.2e-05" ixz="-5e-06"/>
  </inertial>
  <visual>
    <origin xyz="0 0 0" rpy="0 0 0"/>
    <geometry>
      <mesh filename="package://Robot_description/meshes/Lidar.stl" scale="0.001 0.001 0.001"/>
    </geometry>
    <material name="Robot_silver"/>
  </visual>
  <collision>
    <origin xyz="0 0 0" rpy="0 0 0"/>
    <geometry>
      <mesh filename="package://Robot_description/meshes/Lidar.stl" scale="0.001 0.001 0.001"/>
    </geometry>
  </collision>
</link>

<link name="${prefix}top">
  <inertial>
    <origin xyz="-0.04975126669729712 0.13454504753394347 -0.07147065747859381" rpy="0 0 0"/>
    <mass value="0.2279639999999998"/>
    <inertia ixx="0.000172" iyy="0.000283" izz="0.000172" ixy="0.0" iyz="0.0" ixz="-0.0"/>
  </inertial>
  <visual>
    <origin xyz="0 0 0" rpy="0 0 0"/>
    <geometry>
      <mesh filename="package://Robot_description/meshes/top.stl" scale="0.001 0.001 0.001"/>
    </geometry>
    <material name="Robot_silver"/>
  </visual>
  <collision>
    <origin xyz="0 0 0" rpy="0 0 0"/>
    <geometry>
      <mesh filename="package://Robot_description/meshes/top.stl" scale="0.001 0.001 0.001"/>
    </geometry>
  </collision>
</link>

<link name="${prefix}column">
  <inertial>
    <origin xyz="-0.13975126669729732 0.07621860125295168 -0.08647065747859269" rpy="0 0 0"/>
    <mass value="0.11532475808650255"/>
    <inertia ixx="4.3e-05" iyy="4e-06" izz="4.3e-05" ixy="0.0" iyz="0.0" ixz="0.0"/>
  </inertial>
  <visual>
    <origin xyz="0 0 0" rpy="0 0 0"/>
    <geometry>
      <mesh filename="package://Robot_description/meshes/column.stl" scale="0.001 0.001 0.001"/>
    </geometry>
    <material name="Robot_silver"/>
  </visual>
  <collision>
    <origin xyz="0 0 0" rpy="0 0 0"/>
    <geometry>
      <mesh filename="package://Robot_description/meshes/column.stl" scale="0.001 0.001 0.001"/>
    </geometry>
  </collision>
</link>

<link name="${prefix}Second">
  <inertial>
    <origin xyz="-0.05476322059836039 0.11396169039083541 0.04553791572663135" rpy="0 0 0"/>
    <mass value="2.4299326702154507"/>
    <inertia ixx="0.017518" iyy="0.027183" izz="0.010271" ixy="0.000781" iyz="-0.001045" ixz="0.002711"/>
  </inertial>
  <visual>
    <origin xyz="0 0 0" rpy="0 0 0"/>
    <geometry>
      <mesh filename="package://Robot_description/meshes/Second.stl" scale="0.001 0.001 0.001"/>
    </geometry>
    <material name="Robot_silver"/>
  </visual>
  <collision>
    <origin xyz="0 0 0" rpy="0 0 0"/>
    <geometry>
      <mesh filename="package://Robot_description/meshes/Second.stl" scale="0.001 0.001 0.001"/>
    </geometry>
  </collision>
</link>

<link name="${prefix}One">
  <inertial>
    <origin xyz="0.03157012375964665 0.016218619447756693 -0.0547861981409786" rpy="0 0 0"/>
    <mass value="0.10603593864483289"/>
    <inertia ixx="6e-06" iyy="3.1e-05" izz="3.3e-05" ixy="-0.0" iyz="-0.0" ixz="-3e-06"/>
  </inertial>
  <visual>
    <origin xyz="0 0 0" rpy="0 0 0"/>
    <geometry>
      <mesh filename="package://Robot_description/meshes/One.stl" scale="0.001 0.001 0.001"/>
    </geometry>
    <material name="Robot_silver"/>
  </visual>
  <collision>
    <origin xyz="0 0 0" rpy="0 0 0"/>
    <geometry>
      <mesh filename="package://Robot_description/meshes/One.stl" scale="0.001 0.001 0.001"/>
    </geometry>
  </collision>
</link>

<link name="${prefix}RC">
  <inertial>
    <origin xyz="0.0 0.0 0.0" rpy="0 0 0"/>
    <mass value="0.001"/>
    <inertia ixx="1e-06" iyy="1e-06" izz="1e-06" ixy="0.0" iyz="0.0" ixz="0.0"/>
  </inertial>
  <visual>
    <origin xyz="0 0 0" rpy="0 0 0"/>
    <geometry>
      <mesh filename="package://Robot_description/meshes/RC.stl" scale="0.001 0.001 0.001"/>
    </geometry>
    <material name="Robot_silver"/>
  </visual>
  <collision>
    <origin xyz="0 0 0" rpy="0 0 0"/>
    <geometry>
      <mesh filename="package://Robot_description/meshes/RC.stl" scale="0.001 0.001 0.001"/>
    </geometry>
  </collision>
</link>

<link name="${prefix}batteryCase18650x3">
  <inertial>
    <origin xyz="7.926961599036373e-05 0.010008616809429669 3.0183839432513313e-05" rpy="0 0 0"/>
    <mass value="0.13821989838774607"/>
    <inertia ixx="9.6e-05" iyy="0.000144" izz="5.5e-05" ixy="0.0" iyz="-0.0" ixz="0.0"/>
  </inertial>
  <visual>
    <origin xyz="0 0 0" rpy="0 0 0"/>
    <geometry>
      <mesh filename="package://Robot_description/meshes/batteryCase18650x3.stl" scale="0.001 0.001 0.001"/>
    </geometry>
    <material name="Robot_silver"/>
  </visual>
  <collision>
    <origin xyz="0 0 0" rpy="0 0 0"/>
    <geometry>
      <mesh filename="package://Robot_description/meshes/batteryCase18650x3.stl" scale="0.001 0.001 0.001"/>
    </geometry>
  </collision>
</link>

<link name="${prefix}65mm">
  <inertial>
    <origin xyz="0.08337588380789734 0.016218605686849793 -0.0523493615238644" rpy="0 0 0"/>
    <mass value="0.27418981426105904"/>
    <inertia ixx="0.000202" iyy="0.00012" izz="0.00012" ixy="-0.0" iyz="-0.0" ixz="-0.0"/>
  </inertial>
  <visual>
    <origin xyz="0 0 0" rpy="0 0 0"/>
    <geometry>
      <mesh filename="package://Robot_description/meshes/65mm.stl" scale="0.001 0.001 0.001"/>
    </geometry>
    <material name="Robot_silver"/>
  </visual>
  <collision>
    <origin xyz="0 0 0" rpy="0 0 0"/>
    <geometry>
      <mesh filename="package://Robot_description/meshes/65mm.stl" scale="0.001 0.001 0.001"/>
    </geometry>
  </collision>
</link>

<link name="${prefix}rigid_group_1">
  <inertial>
    <origin xyz="0.0 0.0 0.0" rpy="0 0 0"/>
    <mass value="0.0"/>
    <inertia ixx="0.0" iyy="0.0" izz="0.0" ixy="0.0" iyz="0.0" ixz="0.0"/>
  </inertial>
  <visual>
    <origin xyz="0 0 0" rpy="0 0 0"/>
    <geometry>
      <mesh filename="package://Robot_description/meshes/rigid_group_1.stl" scale="0.001 0.001 0.001"/>
    </geometry>
    <material name="Robot_silver"/>
  </visual>
  <collision>
    <origin xyz="0 0 0" rpy="0 0 0"/>
    <geometry>
      <mesh filename="package://Robot_description/meshes/rigid_group_1.stl" scale="0.001 0.001 0.001"/>
    </geometry>
  </collision>
</link>

<joint name="${prefix}Rigid 2" type="fixed">
  <origin xyz="-0.118751 0.038719 0.113529" rpy="0 0 0"/>
  <parent link="${prefix}base_link"/>
  <child link="${prefix}37"/>
</joint>

<joint name="${prefix}Rigid 3" type="fixed">
  <origin xyz="-0.118751 0.038719 0.113529" rpy="0 0 0"/>
  <parent link="${prefix}base_link"/>
  <child link="${prefix}37"/>
</joint>

<joint name="${prefix}Rigid 4" type="fixed">
  <origin xyz="-0.118751 0.038719 0.113529" rpy="0 0 0"/>
  <parent link="${prefix}base_link"/>
  <child link="${prefix}37"/>
</joint>

<joint name="${prefix}Rigid 5" type="fixed">
  <origin xyz="-0.118751 0.038719 0.113529" rpy="0 0 0"/>
  <parent link="${prefix}base_link"/>
  <child link="${prefix}37"/>
</joint>

<joint name="${prefix}Rigid 41" type="fixed">
  <origin xyz="0.055 0.005 -0.0475" rpy="0 0 0"/>
  <parent link="${prefix}Second"/>
  <child link="${prefix}Lidar"/>
</joint>

<joint name="${prefix}Rigid 46" type="fixed">
  <origin xyz="0.09 0.005 -0.26" rpy="0 0 0"/>
  <parent link="${prefix}Second"/>
  <child link="${prefix}top"/>
</joint>

<joint name="${prefix}Rigid 51" type="fixed">
  <origin xyz="0.040249 0.043719 0.163529" rpy="0 0 0"/>
  <parent link="${prefix}base_link"/>
  <child link="${prefix}column"/>
</joint>

<joint name="${prefix}Rigid 52" type="fixed">
  <origin xyz="0.040249 0.043719 0.163529" rpy="0 0 0"/>
  <parent link="${prefix}base_link"/>
  <child link="${prefix}column"/>
</joint>

<joint name="${prefix}Rigid 53" type="fixed">
  <origin xyz="0.040249 0.043719 0.163529" rpy="0 0 0"/>
  <parent link="${prefix}base_link"/>
  <child link="${prefix}column"/>
</joint>

<joint name="${prefix}Rigid 54" type="fixed">
  <origin xyz="0.040249 0.043719 0.163529" rpy="0 0 0"/>
  <parent link="${prefix}base_link"/>
  <child link="${prefix}column"/>
</joint>

<joint name="${prefix}Rigid 55" type="fixed">
  <origin xyz="0.040249 0.043719 0.163529" rpy="0 0 0"/>
  <parent link="${prefix}base_link"/>
  <child link="${prefix}column"/>
</joint>

<joint name="${prefix}Rigid 56" type="fixed">
  <origin xyz="0.040249 0.043719 0.163529" rpy="0 0 0"/>
  <parent link="${prefix}base_link"/>
  <child link="${prefix}column"/>
</joint>

<joint name="${prefix}Rigid 57" type="fixed">
  <origin xyz="-0.18 0.065 0.0" rpy="0 0 0"/>
  <parent link="${prefix}column"/>
  <child link="${prefix}Second"/>
</joint>

<joint name="${prefix}Rigid 58" type="fixed">
  <origin xyz="0.139631 -0.0115 -0.17" rpy="0 0 0"/>
  <parent link="${prefix}37"/>
  <child link="${prefix}One"/>
</joint>

<joint name="${prefix}Revolute 59" type="continuous">
  <origin xyz="0.04475 -0.011 0.004125" rpy="0 0 0"/>
  <parent link="${prefix}One"/>
  <child link="${prefix}RC"/>
  <axis xyz="1.0 0.0 -0.0"/>
</joint>

<joint name="${prefix}Rigid 60" type="fixed">
  <origin xyz="0.139631 -0.0115 -0.17" rpy="0 0 0"/>
  <parent link="${prefix}37"/>
  <child link="${prefix}One"/>
</joint>

<joint name="${prefix}Revolute 61" type="continuous">
  <origin xyz="0.04475 -0.011 0.004125" rpy="0 0 0"/>
  <parent link="${prefix}One"/>
  <child link="${prefix}RC"/>
  <axis xyz="1.0 0.0 -0.0"/>
</joint>

<joint name="${prefix}Rigid 62" type="fixed">
  <origin xyz="0.139631 -0.0115 -0.17" rpy="0 0 0"/>
  <parent link="${prefix}37"/>
  <child link="${prefix}One"/>
</joint>

<joint name="${prefix}Revolute 63" type="continuous">
  <origin xyz="0.04475 -0.011 0.004125" rpy="0 0 0"/>
  <parent link="${prefix}One"/>
  <child link="${prefix}RC"/>
  <axis xyz="-1.0 0.0 0.0"/>
</joint>

<joint name="${prefix}Rigid 64" type="fixed">
  <origin xyz="0.139631 -0.0115 -0.17" rpy="0 0 0"/>
  <parent link="${prefix}37"/>
  <child link="${prefix}One"/>
</joint>

<joint name="${prefix}Revolute 65" type="continuous">
  <origin xyz="0.04475 -0.011 0.004125" rpy="0 0 0"/>
  <parent link="${prefix}One"/>
  <child link="${prefix}RC"/>
  <axis xyz="-1.0 -0.0 0.0"/>
</joint>

</xacro:macro>
</robot>
